Task "{{ task.name }}" failed at {{ datetime }} due to following errors:

{{ error | safe }}
